Попробуем поменять входные данные теста.  
sum() должен принимать на вход другие списки числового типа, например дроби.

Создадим проект project и поменяем тест кейс.


Если вы запустите тесты повторно с python -m unittest test, получите следующее:

$ python -m unittest test
F.
======================================================================
FAIL: test_list_fraction (test.TestSum)
---
Traceback (most recent call last):
  File "test.py", line 21, in test_list_fraction
    self.assertEqual(result, 1)
AssertionError: Fraction(9, 10) != 1

----
Ran 2 tests in 0.001s

FAILED (failures=1)

В этих выходных данных вы видите следующее:

В первой строке указаны результаты выполнения всех тестов: один проваленный (F), один пройденный (.);  
FAIL показывает некоторые детали проваленного теста:

Название тестового метода (test_list_fraction);
Тестовый модуль (test) и тест-кейс (TestSum);  
Трейсбек строки с ошибкой;  
Детали утверждения с ожидаемым результатом (1) и фактическим результатом (Fraction(9, 10)) 

Помните,  
можно добавить дополнительную информацию к выходным данным теста с помощью флага -v к команде python -m unittest.
